Workbook

Sheet Dimensions
A2: NHÀ THỜ GIÁO XỨ THẠCH BI
A4: Kích thước bản vẽ và quy đổi cho mô hình 3D / Drawing dimensions and 3D model units
A7: Mã / ID | B7: Bộ phận / Part | C7: Thông số / Parameter | D7: Trục và mốc / Axes and refs | E7: Trị số gốc / Source value | F7: ĐVT / Unit | G7: Kích thước (mm) | H7: Quy đổi (m) | I7: Cơ sở / Basis | J7: Tờ / Drawing | K7: Vị trí / Locator | L7: Nhãn gốc / Printed label | M7: Ghi chú / Notes
A8: P001 | B8: Lưới trục dọc Longitudinal grid | C8: axis_spacing | D8: Model: X Source: longitudinal 1 → 2 | E8: 4900 | F8: mm | G8: =IF(COUNTBLANK(E8)>0,"",E8) -> 4900 | H8: =IF(COUNTBLANK(G8)>0,"",G8/1000) -> 4.9 | I8: Ghi trên bản vẽ / Explicit | J8: Tờ 6 File 4 | K8: Bottom longitudinal dimension chain | L8: 4900
A9: P002 | B9: Lưới trục dọc Longitudinal grid | C9: axis_spacing | D9: Model: X Source: longitudinal 2 → 2′ | E9: 575 | F9: mm | G9: =IF(COUNTBLANK(E9)>0,"",E9) -> 575 | H9: =IF(COUNTBLANK(G9)>0,"",G9/1000) -> 0.575 | I9: Ghi trên bản vẽ / Explicit | J9: Tờ 6 File 4 | K9: Bottom longitudinal dimension chain | L9: 575
A10: P003 | B10: Lưới trục dọc Longitudinal grid | C10: axis_spacing | D10: Model: X Source: longitudinal 2′ → 3 | E10: 4500 | F10: mm | G10: =IF(COUNTBLANK(E10)>0,"",E10) -> 4500 | H10: =IF(COUNTBLANK(G10)>0,"",G10/1000) -> 4.5 | I10: Ghi trên bản vẽ / Explicit | J10: Tờ 6 File 4 | K10: Bottom longitudinal dimension chain | L10: 4500
A11: P004 | B11: Lưới trục dọc Longitudinal grid | C11: axis_spacing | D11: Model: X Source: longitudinal 3 → 4 | E11: 4500 | F11: mm | G11: =IF(COUNTBLANK(E11)>0,"",E11) -> 4500 | H11: =IF(COUNTBLANK(G11)>0,"",G11/1000) -> 4.5 | I11: Ghi trên bản vẽ / Explicit | J11: Tờ 6 File 4 | K11: Bottom longitudinal dimension chain | L11: 4500
A12: P005 | B12: Lưới trục dọc Longitudinal grid | C12: axis_spacing | D12: Model: X Source: longitudinal 4 → 5 | E12: 4500 | F12: mm | G12: =IF(COUNTBLANK(E12)>0,"",E12) -> 4500 | H12: =IF(COUNTBLANK(G12)>0,"",G12/1000) -> 4.5 | I12: Ghi trên bản vẽ / Explicit | J12: Tờ 6 File 4 | K12: Bottom longitudinal dimension chain | L12: 4500
A13: P006 | B13: Lưới trục dọc Longitudinal grid | C13: axis_spacing | D13: Model: X Source: longitudinal 5 → 6 | E13: 4500 | F13: mm | G13: =IF(COUNTBLANK(E13)>0,"",E13) -> 4500 | H13: =IF(COUNTBLANK(G13)>0,"",G13/1000) -> 4.5 | I13: Ghi trên bản vẽ / Explicit | J13: Tờ 6 File 4 | K13: Bottom longitudinal dimension chain | L13: 4500
A14: P007 | B14: Lưới trục dọc Longitudinal grid | C14: axis_spacing | D14: Model: X Source: longitudinal 6 → 7 | E14: 4500 | F14: mm | G14: =IF(COUNTBLANK(E14)>0,"",E14) -> 4500 | H14: =IF(COUNTBLANK(G14)>0,"",G14/1000) -> 4.5 | I14: Ghi trên bản vẽ / Explicit | J14: Tờ 6 File 4 | K14: Bottom longitudinal dimension chain | L14: 4500
A15: P008 | B15: Lưới trục dọc Longitudinal grid | C15: axis_spacing | D15: Model: X Source: longitudinal 7 → 8 | E15: 4500 | F15: mm | G15: =IF(COUNTBLANK(E15)>0,"",E15) -> 4500 | H15: =IF(COUNTBLANK(G15)>0,"",G15/1000) -> 4.5 | I15: Ghi trên bản vẽ / Explicit | J15: Tờ 6 File 4 | K15: Bottom longitudinal dimension chain | L15: 4500
A16: P009 | B16: Lưới trục dọc Longitudinal grid | C16: axis_spacing | D16: Model: X Source: longitudinal 8 → 9 | E16: 4500 | F16: mm | G16: =IF(COUNTBLANK(E16)>0,"",E16) -> 4500 | H16: =IF(COUNTBLANK(G16)>0,"",G16/1000) -> 4.5 | I16: Ghi trên bản vẽ / Explicit | J16: Tờ 6 File 4 | K16: Bottom longitudinal dimension chain | L16: 4500
A17: P010 | B17: Lưới trục dọc Longitudinal grid | C17: axis_spacing | D17: Model: X Source: longitudinal 9 → 10 | E17: 7200 | F17: mm | G17: =IF(COUNTBLANK(E17)>0,"",E17) -> 7200 | H17: =IF(COUNTBLANK(G17)>0,"",G17/1000) -> 7.2 | I17: Ghi trên bản vẽ / Explicit | J17: Tờ 6 File 4 | K17: Bottom longitudinal dimension chain | L17: 7200
A18: P011 | B18: Lưới trục dọc Longitudinal grid | C18: axis_spacing | D18: Model: X Source: longitudinal 10 → 11 | E18: 4500 | F18: mm | G18: =IF(COUNTBLANK(E18)>0,"",E18) -> 4500 | H18: =IF(COUNTBLANK(G18)>0,"",G18/1000) -> 4.5 | I18: Ghi trên bản vẽ / Explicit | J18: Tờ 6 File 4 | K18: Bottom longitudinal dimension chain | L18: 4500
A19: P012 | B19: Lưới trục dọc Longitudinal grid | C19: axis_spacing | D19: Model: X Source: longitudinal 11 → 12 | E19: 4341 | F19: mm | G19: =IF(COUNTBLANK(E19)>0,"",E19) -> 4341 | H19: =IF(COUNTBLANK(G19)>0,"",G19/1000) -> 4.341 | I19: Ghi trên bản vẽ / Explicit | J19: Tờ 6 File 4 | K19: Bottom longitudinal dimension chain | L19: 4341
A20: P013 | B20: Lưới trục ngang Transverse grid | C20: axis_spacing | D20: Model: Z Source: transverse A → B | E20: 2835 | F20: mm | G20: =IF(COUNTBLANK(E20)>0,"",E20) -> 2835 | H20: =IF(COUNTBLANK(G20)>0,"",G20/1000) -> 2.835 | I20: Ghi trên bản vẽ / Explicit | J20: Tờ 6 File 4 | K20: Far-left transverse dimension chain | L20: 2835 | M20: Tiny CAD text recovered with a temporary reduced-stroke reading render; original PDF unchanged.
A21: P014 | B21: Lưới trục ngang Transverse grid | C21: axis_spacing | D21: Model: Z Source: transverse B → C | E21: 3054 | F21: mm | G21: =IF(COUNTBLANK(E21)>0,"",E21) -> 3054 | H21: =IF(COUNTBLANK(G21)>0,"",G21/1000) -> 3.054 | I21: Ghi trên bản vẽ / Explicit | J21: Tờ 6 File 4 | K21: Far-left transverse dimension chain | L21: 3054
A22: P015 | B22: Lưới trục ngang Transverse grid | C22: axis_spacing | D22: Model: Z Source: transverse C → D | E22: 3760 | F22: mm | G22: =IF(COUNTBLANK(E22)>0,"",E22) -> 3760 | H22: =IF(COUNTBLANK(G22)>0,"",G22/1000) -> 3.76 | I22: Ghi trên bản vẽ / Explicit | J22: Tờ 6 File 4 | K22: Far-left transverse dimension chain | L22: 3760
A23: P016 | B23: Lưới trục ngang Transverse grid | C23: axis_spacing | D23: Model: Z Source: transverse D → E | E23: 7200 | F23: mm | G23: =IF(COUNTBLANK(E23)>0,"",E23) -> 7200 | H23: =IF(COUNTBLANK(G23)>0,"",G23/1000) -> 7.2 | I23: Ghi trên bản vẽ / Explicit | J23: Tờ 6 File 4 | K23: Far-left transverse dimension chain | L23: 7200
A24: P017 | B24: Lưới trục ngang Transverse grid | C24: axis_spacing | D24: Model: Z Source: transverse E → G | E24: 3760 | F24: mm | G24: =IF(COUNTBLANK(E24)>0,"",E24) -> 3760 | H24: =IF(COUNTBLANK(G24)>0,"",G24/1000) -> 3.76 | I24: Ghi trên bản vẽ / Explicit | J24: Tờ 6 File 4 | K24: Far-left transverse dimension chain | L24: 3760
A25: P018 | B25: Lưới trục ngang Transverse grid | C25: axis_spacing | D25: Model: Z Source: transverse G → H | E25: 3054 | F25: mm | G25: =IF(COUNTBLANK(E25)>0,"",E25) -> 3054 | H25: =IF(COUNTBLANK(G25)>0,"",G25/1000) -> 3.054 | I25: Ghi trên bản vẽ / Explicit | J25: Tờ 6 File 4 | K25: Far-left transverse dimension chain | L25: 3054
A26: P019 | B26: Lưới trục ngang Transverse grid | C26: axis_spacing | D26: Model: Z Source: transverse H → I | E26: 2835 | F26: mm | G26: =IF(COUNTBLANK(E26)>0,"",E26) -> 2835 | H26: =IF(COUNTBLANK(G26)>0,"",G26/1000) -> 2.835 | I26: Ghi trên bản vẽ / Explicit | J26: Tờ 6 File 4 | K26: Far-left transverse dimension chain | L26: 2835 | M26: Tiny CAD text recovered with a temporary reduced-stroke reading render; original PDF unchanged.
A27: P020 | B27: Kích thước bao công trình Exterior envelope | C27: overall_length | D27: Model: X Source: longitudinal forecourt/front landing outer end → 1 | E27: 13219 | F27: mm | G27: =IF(COUNTBLANK(E27)>0,"",E27) -> 13219 | H27: =IF(COUNTBLANK(G27)>0,"",G27/1000) -> 13.219 | I27: Ghi trên bản vẽ / Explicit | J27: Tờ 6 File 4 | K27: Bottom left chain | L27: 13219
A28: P021 | B28: Kích thước bao công trình Exterior envelope | C28: overall_length | D28: Model: X Source: longitudinal forecourt/front landing outer end → rear exterior end | E28: 67064 | F28: mm | G28: =IF(COUNTBLANK(E28)>0,"",E28) -> 67064 | H28: =IF(COUNTBLANK(G28)>0,"",G28/1000) -> 67.064 | I28: Ghi trên bản vẽ / Explicit | J28: Tờ 6 File 4 | K28: Bottom overall chain | L28: 67064
A29: P022 | B29: Kích thước bao công trình Exterior envelope | C29: overall_length | D29: Model: X Source: longitudinal front tower exterior end → rear exterior end | E29: 54794 | F29: mm | G29: =IF(COUNTBLANK(E29)>0,"",E29) -> 54794 | H29: =IF(COUNTBLANK(G29)>0,"",G29/1000) -> 54.794 | I29: Ghi trên bản vẽ / Explicit | J29: Tờ 6 File 4 | K29: Top overall chain | L29: 54794 | M29: Top overall label was recovered with a temporary reduced-stroke reading render.
A30: P023 | B30: Kích thước bao công trình Exterior envelope | C30: edge_offset | D30: Model: Z Source: transverse upper outside edge near H → H | E30: 832 | F30: mm | G30: =IF(COUNTBLANK(E30)>0,"",E30) -> 832 | H30: =IF(COUNTBLANK(G30)>0,"",G30/1000) -> 0.832 | I30: Ghi trên bản vẽ / Explicit | J30: Tờ 6 File 4 | K30: Right outer main-body margin, above H | L30: 832
A31: P024 | B31: Kích thước bao công trình Exterior envelope | C31: edge_offset | D31: Model: Z Source: transverse B → lower outside edge near B | E31: 829 | F31: mm | G31: =IF(COUNTBLANK(E31)>0,"",E31) -> 829 | H31: =IF(COUNTBLANK(G31)>0,"",G31/1000) -> 0.829 | I31: Ghi trên bản vẽ / Explicit | J31: Tờ 6 File 4 | K31: Right outer main-body margin, below B | L31: 829
A32: P025 | B32: Kích thước bao công trình Exterior envelope | C32: edge_offset | D32: Model: Z Source: transverse A → lower transept exterior edge | E32: 829 | F32: mm | G32: =IF(COUNTBLANK(E32)>0,"",E32) -> 829 | H32: =IF(COUNTBLANK(G32)>0,"",G32/1000) -> 0.829 | I32: Ghi trên bản vẽ / Explicit | J32: Tờ 6 File 4 | K32: Right lowermost short offset, below A | L32: 829
A33: P026 | B33: Kích thước mặt bằng Main body | C33: overall_width | D33: Model: Z Source: transverse main upper exterior edge → main lower exterior edge | E33: 22489 | F33: mm | G33: =IF(COUNTBLANK(E33)>0,"",E33) -> 22489 | H33: =IF(COUNTBLANK(G33)>0,"",G33/1000) -> 22.489 | I33: Ghi trên bản vẽ / Explicit | J33: Tờ 6 File 4 | K33: Right middle overall dimension | L33: 22489 | M33: 832 + 3054 + 3760 + 7200 + 3760 + 3054 + 829 = 22489.
A34: P027 | B34: Kích thước mặt bằng Transept wings | C34: overall_width | D34: Model: Z Source: transverse upper wing exterior edge → lower wing exterior edge | E34: 28158 | F34: mm | G34: =IF(COUNTBLANK(E34)>0,"",E34) -> 28158 | H34: =IF(COUNTBLANK(G34)>0,"",G34/1000) -> 28.158 | I34: Ghi trên bản vẽ / Explicit | J34: Tờ 6 File 4 | K34: Right outermost overall dimension | L34: 28158 | M34: Do not replace with main-body width22489. Axis A–I total26498; assigning both832 and829 to wing edges would yield28159, 1mm above printed overall.
A35: P028 | B35: Kích thước mặt bằng Transept interior | C35: clear_width | D35: Model: Z Source: transverse upper wing inner wall face → lower wing inner wall face | E35: 26168 | F35: mm | G35: =IF(COUNTBLANK(E35)>0,"",E35) -> 26168 | H35: =IF(COUNTBLANK(G35)>0,"",G35/1000) -> 26.168 | I35: Ghi trên bản vẽ / Explicit | J35: Tờ 6 File 4 | K35: Vertical dimension inside bay9–10 | L35: 26168 | M35: Dimension spans interior faces of opposing transverse wing walls.
A36: P029 | B36: Kích thước mặt bằng Nave interior | C36: clear_width | D36: Model: Z Source: transverse inner face near G → inner face near C | E36: 14500 | F36: mm | G36: =IF(COUNTBLANK(E36)>0,"",E36) -> 14500 | H36: =IF(COUNTBLANK(G36)>0,"",G36/1000) -> 14.5 | I36: Ghi trên bản vẽ / Explicit | J36: Tờ 6 File 4 | K36: Vertical dimension near bay5–6 | L36: 14500 | M36: Grid G–C14720 is a different measurement.
A37: P030 | B37: Kích thước mặt bằng Main interior | C37: clear_length | D37: Model: X Source: longitudinal inside front wall near2′ → inside rear wall near12 | E37: 47386 | F37: mm | G37: =IF(COUNTBLANK(E37)>0,"",E37) -> 47386 | H37: =IF(COUNTBLANK(G37)>0,"",G37/1000) -> 47.386 | I37: Ghi trên bản vẽ / Explicit | J37: Tờ 6 File 4 | K37: Horizontal internal dimension near lower nave | L37: 47386 | M37: This is a clear overall interior dimension, not an axis span.
A38: P031 | B38: Kích thước mặt bằng Lower veranda | C38: clear_width | D38: Model: Z Source: transverse inner face near C → inner face near B | E38: 2779 | F38: mm | G38: =IF(COUNTBLANK(E38)>0,"",E38) -> 2779 | H38: =IF(COUNTBLANK(G38)>0,"",G38/1000) -> 2.779 | I38: Ghi trên bản vẽ / Explicit | J38: Tờ 6 File 4 | K38: Lower veranda width dimension near bay3–4 | L38: 2779 | M38: No identical opposite-veranda clear dimension printed.
A39: P032 | B39: Kích thước mặt bằng Transverse wing at9–10 | C39: longitudinal_span | D39: Model: X Source: longitudinal 9 → 10 | E39: 7200 | F39: mm | G39: =IF(COUNTBLANK(E39)>0,"",E39) -> 7200 | H39: =IF(COUNTBLANK(G39)>0,"",G39/1000) -> 7.2 | I39: Ghi trên bản vẽ / Explicit | J39: Tờ 6 File 4 | K39: Top wing dimension chain; repeated inside lower wing | L39: 7200 | M39: Grid span, not clear room width.
A40: P033 | B40: Kích thước mặt bằng Upper transverse wing | C40: front_end_projection | D40: Model: X Source: longitudinal wing front exterior edge → 9 | E40: 995 | F40: mm | G40: =IF(COUNTBLANK(E40)>0,"",E40) -> 995 | H40: =IF(COUNTBLANK(G40)>0,"",G40/1000) -> 0.995 | I40: Ghi trên bản vẽ / Explicit | J40: Tờ 6 File 4 | K40: Top wing outer dimension chain | L40: 995
A41: P034 | B41: Kích thước mặt bằng Upper transverse wing | C41: rear_end_projection | D41: Model: X Source: longitudinal 10 → wing rear exterior edge | E41: 993 | F41: mm | G41: =IF(COUNTBLANK(E41)>0,"",E41) -> 993 | H41: =IF(COUNTBLANK(G41)>0,"",G41/1000) -> 0.993 | I41: Ghi trên bản vẽ / Explicit | J41: Tờ 6 File 4 | K41: Top wing outer dimension chain | L41: 993
A42: P035 | B42: Kích thước mặt bằng Upper transverse wing | C42: overall_length | D42: Model: X Source: longitudinal wing front exterior edge → wing rear exterior edge | E42: 9188 | F42: mm | G42: =IF(COUNTBLANK(E42)>0,"",E42) -> 9188 | H42: =IF(COUNTBLANK(G42)>0,"",G42/1000) -> 9.188 | I42: Ghi trên bản vẽ / Explicit | J42: Tờ 6 File 4 | K42: Top wing outer overall chain | L42: 9188 | M42: 995 + 7200 + 993 = 9188.
A43: P036 | B43: Kích thước mặt bằng Lower front tower/recess | C43: clear_width | D43: Model: X Source: longitudinal front inside face → rear inside face | E43: 2770 | F43: mm | G43: =IF(COUNTBLANK(E43)>0,"",E43) -> 2770 | H43: =IF(COUNTBLANK(G43)>0,"",G43/1000) -> 2.77 | I43: Ghi trên bản vẽ / Explicit | J43: Tờ 6 File 4 | K43: Front lower tower horizontal dimension | L43: 2770 | M43: Use detail position in plan; not overall tower footprint.
A44: P037 | B44: Kích thước mặt bằng Lower front tower/recess | C44: clear_depth | D44: Model: Z Source: transverse upper inside face → lower inside face | E44: 2770 | F44: mm | G44: =IF(COUNTBLANK(E44)>0,"",E44) -> 2770 | H44: =IF(COUNTBLANK(G44)>0,"",G44/1000) -> 2.77 | I44: Ghi trên bản vẽ / Explicit | J44: Tờ 6 File 4 | K44: Front lower tower vertical dimension | L44: 2770 | M44: Use detail position in plan; not overall tower footprint.
...

Sheet Model grid
A2: TỌA ĐỘ MÔ HÌNH / MODEL COORDINATES
A4: X=0 tại trục 1. Y=0 tại sàn gian chính. Z=0 tại trung điểm D–E; Z dương về H/I.
A7: Trục 3D / Axis | B7: Trục hoặc cao độ / Grid or level | C7: Bước trục (mm) | D7: Tọa độ (mm) | E7: Tọa độ (m) | F7: Mã nguồn / Source ID | G7: Cơ sở / Basis | H7: Ghi chú / Notes
A8: X | B8: 1 | D8: =IF(OR(COUNTBLANK('Dimensions'!G135)>0),"",'Dimensions'!G135) -> 0 | E8: =IF(COUNTBLANK(D8)>0,"",D8/1000) -> 0 | F8: P128 | G8: Model coordinate origin | H8: X=0 tại trục 1. Y=0 tại sàn gian chính. Z=0 tại trung điểm D–E; Z dương về H/I.
A9: X | B9: 2 | C9: =IF(OR(COUNTBLANK('Dimensions'!G8)>0),"",'Dimensions'!G8) -> 4900 | D9: =IF(OR(COUNTBLANK('Dimensions'!G136)>0),"",'Dimensions'!G136) -> 4900 | E9: =IF(COUNTBLANK(D9)>0,"",D9/1000) -> 4.9 | F9: P001, P129 | G9: Cumulative plan grid | H9: Tâm trục / Grid centerline
A10: X | B10: 2′ | C10: =IF(OR(COUNTBLANK('Dimensions'!G9)>0),"",'Dimensions'!G9) -> 575 | D10: =IF(OR(COUNTBLANK('Dimensions'!G137)>0),"",'Dimensions'!G137) -> 5475 | E10: =IF(COUNTBLANK(D10)>0,"",D10/1000) -> 5.475 | F10: P002, P130 | G10: Cumulative plan grid | H10: Tâm trục / Grid centerline
A11: X | B11: 3 | C11: =IF(OR(COUNTBLANK('Dimensions'!G10)>0),"",'Dimensions'!G10) -> 4500 | D11: =IF(OR(COUNTBLANK('Dimensions'!G138)>0),"",'Dimensions'!G138) -> 9975 | E11: =IF(COUNTBLANK(D11)>0,"",D11/1000) -> 9.975 | F11: P003, P131 | G11: Cumulative plan grid | H11: Tâm trục / Grid centerline
A12: X | B12: 4 | C12: =IF(OR(COUNTBLANK('Dimensions'!G11)>0),"",'Dimensions'!G11) -> 4500 | D12: =IF(OR(COUNTBLANK('Dimensions'!G139)>0),"",'Dimensions'!G139) -> 14475 | E12: =IF(COUNTBLANK(D12)>0,"",D12/1000) -> 14.475 | F12: P004, P132 | G12: Cumulative plan grid | H12: Tâm trục / Grid centerline
A13: X | B13: 5 | C13: =IF(OR(COUNTBLANK('Dimensions'!G12)>0),"",'Dimensions'!G12) -> 4500 | D13: =IF(OR(COUNTBLANK('Dimensions'!G140)>0),"",'Dimensions'!G140) -> 18975 | E13: =IF(COUNTBLANK(D13)>0,"",D13/1000) -> 18.975 | F13: P005, P133 | G13: Cumulative plan grid | H13: Tâm trục / Grid centerline
A14: X | B14: 6 | C14: =IF(OR(COUNTBLANK('Dimensions'!G13)>0),"",'Dimensions'!G13) -> 4500 | D14: =IF(OR(COUNTBLANK('Dimensions'!G141)>0),"",'Dimensions'!G141) -> 23475 | E14: =IF(COUNTBLANK(D14)>0,"",D14/1000) -> 23.475 | F14: P006, P134 | G14: Cumulative plan grid | H14: Tâm trục / Grid centerline
A15: X | B15: 7 | C15: =IF(OR(COUNTBLANK('Dimensions'!G14)>0),"",'Dimensions'!G14) -> 4500 | D15: =IF(OR(COUNTBLANK('Dimensions'!G142)>0),"",'Dimensions'!G142) -> 27975 | E15: =IF(COUNTBLANK(D15)>0,"",D15/1000) -> 27.975 | F15: P007, P135 | G15: Cumulative plan grid | H15: Tâm trục / Grid centerline
A16: X | B16: 8 | C16: =IF(OR(COUNTBLANK('Dimensions'!G15)>0),"",'Dimensions'!G15) -> 4500 | D16: =IF(OR(COUNTBLANK('Dimensions'!G143)>0),"",'Dimensions'!G143) -> 32475 | E16: =IF(COUNTBLANK(D16)>0,"",D16/1000) -> 32.475 | F16: P008, P136 | G16: Cumulative plan grid | H16: Tâm trục / Grid centerline
A17: X | B17: 9 | C17: =IF(OR(COUNTBLANK('Dimensions'!G16)>0),"",'Dimensions'!G16) -> 4500 | D17: =IF(OR(COUNTBLANK('Dimensions'!G144)>0),"",'Dimensions'!G144) -> 36975 | E17: =IF(COUNTBLANK(D17)>0,"",D17/1000) -> 36.975 | F17: P009, P137 | G17: Cumulative plan grid | H17: Tâm trục / Grid centerline
A18: X | B18: 10 | C18: =IF(OR(COUNTBLANK('Dimensions'!G17)>0),"",'Dimensions'!G17) -> 7200 | D18: =IF(OR(COUNTBLANK('Dimensions'!G145)>0),"",'Dimensions'!G145) -> 44175 | E18: =IF(COUNTBLANK(D18)>0,"",D18/1000) -> 44.175 | F18: P010, P138 | G18: Cumulative plan grid | H18: Tâm trục / Grid centerline
A19: X | B19: 11 | C19: =IF(OR(COUNTBLANK('Dimensions'!G18)>0),"",'Dimensions'!G18) -> 4500 | D19: =IF(OR(COUNTBLANK('Dimensions'!G146)>0),"",'Dimensions'!G146) -> 48675 | E19: =IF(COUNTBLANK(D19)>0,"",D19/1000) -> 48.675 | F19: P011, P139 | G19: Cumulative plan grid | H19: Tâm trục / Grid centerline
A20: X | B20: 12 | C20: =IF(OR(COUNTBLANK('Dimensions'!G19)>0),"",'Dimensions'!G19) -> 4341 | D20: =IF(OR(COUNTBLANK('Dimensions'!G147)>0),"",'Dimensions'!G147) -> 53016 | E20: =IF(COUNTBLANK(D20)>0,"",D20/1000) -> 53.016 | F20: P012, P140 | G20: Cumulative plan grid | H20: Tâm trục / Grid centerline
A21: X | B21: Approach toe (plan) | D21: =IF(OR(COUNTBLANK('Dimensions'!G27)>0),"",-'Dimensions'!G27) -> -13219 | E21: =IF(COUNTBLANK(D21)>0,"",D21/1000) -> -13.219 | F21: P020 | G21: Ground plan extent | H21: Tờ 6. Điểm đầu của chuỗi 67,064 mm / Start of 67,064 mm overall chain
A22: X | B22: Rear edge (plan) | D22: =IF(OR(COUNTBLANK('Dimensions'!G147)>0,COUNTBLANK('Dimensions'!G162)>0),"",'Dimensions'!G147+'Dimensions'!G162) -> 53845 | E22: =IF(COUNTBLANK(D22)>0,"",D22/1000) -> 53.845 | F22: P140, P155 | G22: Ground plan extent | H22: Tờ 6. Biên sau nhà theo chuỗi mặt bằng / Rear exterior plan edge
A23: X | B23: Tower front edge (plan) | D23: =IF(OR(COUNTBLANK('Dimensions'!G163)>0),"",-'Dimensions'!G163) -> -949 | E23: =IF(COUNTBLANK(D23)>0,"",D23/1000) -> -0.949 | F23: P156 | G23: Ground plan extent | H23: Tờ 6. Giới hạn tháp trong chuỗi 54,794 mm / Tower front edge in 54,794 mm chain
A24: X | B24: Front edge (roof) | D24: =IF(OR(COUNTBLANK('Dimensions'!G178)>0),"",-'Dimensions'!G178) -> -915 | E24: =IF(COUNTBLANK(D24)>0,"",D24/1000) -> -0.915 | F24: P171 | G24: Roof plan lower chain | H24: Tờ 11. Chuỗi dưới 54,736 mm / Lower 54,736 mm dimension chain
A25: X | B25: Rear edge (roof) | D25: =IF(OR(COUNTBLANK('Dimensions'!G147)>0,COUNTBLANK('Dimensions'!G179)>0),"",'Dimensions'!G147+'Dimensions'!G179) -> 53821 | E25: =IF(COUNTBLANK(D25)>0,"",D25/1000) -> 53.821 | F25: P140, P172 | G25: Roof plan lower chain | H25: Tờ 11. Chuỗi dưới 54,736 mm / Lower 54,736 mm dimension chain
A26: X | B26: Approach toe (elevation) | D26: =IF(OR(COUNTBLANK('Dimensions'!G271)>0),"",-'Dimensions'!G271) -> -13194 | E26: =IF(COUNTBLANK(D26)>0,"",D26/1000) -> -13.194 | F26: E051 | G26: Side elevation extent | H26: Tờ 2. Chuỗi riêng 67,149 mm / Separate 67,149 mm dimension chain
A27: X | B27: Far-end edge (elevation) | D27: =IF(OR(COUNTBLANK('Dimensions'!G302)>0,COUNTBLANK('Dimensions'!G284)>0),"",'Dimensions'!G302+'Dimensions'!G284) -> 53955 | E27: =IF(COUNTBLANK(D27)>0,"",D27/1000) -> 53.955 | F27: E082, E064 | G27: Side elevation extent | H27: Tờ 2. Điểm cuối khác mặt bằng / End witness differs from plan
A28: Z | B28: A | D28: =IF(OR(COUNTBLANK('Dimensions'!G148)>0,COUNTBLANK('Dimensions'!G161)>0),"",'Dimensions'!G148-'Dimensions'!G161) -> -13249 | E28: =IF(COUNTBLANK(D28)>0,"",D28/1000) -> -13.249 | F28: P141, P154 | G28: Centered plan grid | H28: Tâm trục / Grid centerline
A29: Z | B29: B | C29: =IF(OR(COUNTBLANK('Dimensions'!G20)>0),"",'Dimensions'!G20) -> 2835 | D29: =IF(OR(COUNTBLANK('Dimensions'!G149)>0,COUNTBLANK('Dimensions'!G161)>0),"",'Dimensions'!G149-'Dimensions'!G161) -> -10414 | E29: =IF(COUNTBLANK(D29)>0,"",D29/1000) -> -10.414 | F29: P013, P142, P154 | G29: Centered plan grid | H29: Z dương về H/I. Không có trục F / Positive toward H/I. No F axis
A30: Z | B30: C | C30: =IF(OR(COUNTBLANK('Dimensions'!G21)>0),"",'Dimensions'!G21) -> 3054 | D30: =IF(OR(COUNTBLANK('Dimensions'!G150)>0,COUNTBLANK('Dimensions'!G161)>0),"",'Dimensions'!G150-'Dimensions'!G161) -> -7360 | E30: =IF(COUNTBLANK(D30)>0,"",D30/1000) -> -7.36 | F30: P014, P143, P154 | G30: Centered plan grid | H30: Z dương về H/I. Không có trục F / Positive toward H/I. No F axis
A31: Z | B31: D | C31: =IF(OR(COUNTBLANK('Dimensions'!G22)>0),"",'Dimensions'!G22) -> 3760 | D31: =IF(OR(COUNTBLANK('Dimensions'!G151)>0,COUNTBLANK('Dimensions'!G161)>0),"",'Dimensions'!G151-'Dimensions'!G161) -> -3600 | E31: =IF(COUNTBLANK(D31)>0,"",D31/1000) -> -3.6 | F31: P015, P144, P154 | G31: Centered plan grid | H31: Z dương về H/I. Không có trục F / Positive toward H/I. No F axis
A32: Z | B32: E | C32: =IF(OR(COUNTBLANK('Dimensions'!G23)>0),"",'Dimensions'!G23) -> 7200 | D32: =IF(OR(COUNTBLANK('Dimensions'!G152)>0,COUNTBLANK('Dimensions'!G161)>0),"",'Dimensions'!G152-'Dimensions'!G161) -> 3600 | E32: =IF(COUNTBLANK(D32)>0,"",D32/1000) -> 3.6 | F32: P016, P145, P154 | G32: Centered plan grid | H32: Z dương về H/I. Không có trục F / Positive toward H/I. No F axis
A33: Z | B33: G | C33: =IF(OR(COUNTBLANK('Dimensions'!G24)>0),"",'Dimensions'!G24) -> 3760 | D33: =IF(OR(COUNTBLANK('Dimensions'!G153)>0,COUNTBLANK('Dimensions'!G161)>0),"",'Dimensions'!G153-'Dimensions'!G161) -> 7360 | E33: =IF(COUNTBLANK(D33)>0,"",D33/1000) -> 7.36 | F33: P017, P146, P154 | G33: Centered plan grid | H33: Z dương về H/I. Không có trục F / Positive toward H/I. No F axis
A34: Z | B34: H | C34: =IF(OR(COUNTBLANK('Dimensions'!G25)>0),"",'Dimensions'!G25) -> 3054 | D34: =IF(OR(COUNTBLANK('Dimensions'!G154)>0,COUNTBLANK('Dimensions'!G161)>0),"",'Dimensions'!G154-'Dimensions'!G161) -> 10414 | E34: =IF(COUNTBLANK(D34)>0,"",D34/1000) -> 10.414 | F34: P018, P147, P154 | G34: Centered plan grid | H34: Z dương về H/I. Không có trục F / Positive toward H/I. No F axis
A35: Z | B35: I | C35: =IF(OR(COUNTBLANK('Dimensions'!G26)>0),"",'Dimensions'!G26) -> 2835 | D35: =IF(OR(COUNTBLANK('Dimensions'!G155)>0,COUNTBLANK('Dimensions'!G161)>0),"",'Dimensions'!G155-'Dimensions'!G161) -> 13249 | E35: =IF(COUNTBLANK(D35)>0,"",D35/1000) -> 13.249 | F35: P019, P148, P154 | G35: Centered plan grid | H35: Z dương về H/I. Không có trục F / Positive toward H/I. No F axis
A36: Y | B36: Front forecourt/entrance landing | D36: =IF(OR(COUNTBLANK('Dimensions'!G54)>0),"",'Dimensions'!G54) -> -480 | E36: =IF(COUNTBLANK(D36)>0,"",D36/1000) -> -0.48 | F36: P047 | G36: Printed elevation
A37: Y | B37: Side stair landings | D37: =IF(OR(COUNTBLANK('Dimensions'!G55)>0),"",'Dimensions'!G55) -> -320 | E37: =IF(COUNTBLANK(D37)>0,"",D37/1000) -> -0.32 | F37: P048 | G37: Printed elevation
A38: Y | B38: Sanctuary/altar platform | D38: 800 | E38: 0.8 | F38: P049 (PDF 750); DWG0378 | G38: Owner direction 24 Oct 2026 · CAD file 23 Oct 2026 | H38: CAD sections 25 and 45 draw the dais at +0.800 (800 mm dimension, platform lines). The PDF set and the CAD ground-plan label give +0.750 (P049, ISSUE-R04). The model uses +0.800 by owner direction.
A39: Y | B39: Upper rear side room | D39: 160 | E39: 0.16 | F39: P050 (PDF 150); DWG0373 | G39: Owner direction 24 Oct 2026 · CAD file 23 Oct 2026 | H39: CAD section 25 dimensions the side floor 160 mm. The PDF set and the CAD ground-plan labels give +0.150. The model uses +0.160 by owner direction.
A40: Y | B40: Central rear room | D40: =IF(OR(COUNTBLANK('Dimensions'!G58)>0),"",'Dimensions'!G58) -> 150 | E40: =IF(COUNTBLANK(D40)>0,"",D40/1000) -> 0.15 | F40: P051 | G40: Printed elevation
A41: Y | B41: Lower rear side room | D41: 160 | E41: 0.16 | F41: P052 (PDF 150); DWG0373 | G41: Owner direction 24 Oct 2026 · CAD file 23 Oct 2026 | H41: CAD section 25 dimensions the side floor 160 mm. The PDF set and the CAD ground-plan labels give +0.150. The model uses +0.160 by owner direction.
A42: Y | B42: Courtyard grade | D42: =IF(OR(COUNTBLANK('Dimensions'!G221)>0),"",'Dimensions'!G221) -> -2080 | E42: =IF(COUNTBLANK(D42)>0,"",D42/1000) -> -2.08 | F42: E001 | G42: Printed elevation | H42: Same levels also shown on sheet 2. The drawing titles the twin-tower end MẶT ĐỨNG CUỐI.
A43: Y | B43: Floor datum | D43: =IF(OR(COUNTBLANK('Dimensions'!G222)>0),"",'Dimensions'!G222) -> 0 | E43: =IF(COUNTBLANK(D43)>0,"",D43/1000) -> 0 | F43: E002 | G43: Printed elevation | H43: Same levels also shown on sheet 2. The drawing titles the twin-tower end MẶT ĐỨNG CUỐI.
A44: Y | B44: Tower base-stage upper level | D44: =IF(OR(COUNTBLANK('Dimensions'!G223)>0),"",'Dimensions'!G223) -> 8390 | E44: =IF(COUNTBLANK(D44)>0,"",D44/1000) -> 8.39 | F44: E003 | G44: Printed elevation | H44: Same levels also shown on sheet 2. The drawing titles the twin-tower end MẶT ĐỨNG CUỐI.
...

Sheet Open items
A2: KÍCH THƯỚC CẦN XÁC NHẬN / OPEN DIMENSIONS
A4: Giữ nguyên các số ghi khác nhau. Ghi câu trả lời và nguồn mới ở hai cột cuối. / Preserve differing source values.
A7: Mã / ID | B7: Vấn đề / Issue | C7: Bằng chứng / Evidence | D7: Mã nguồn / Source IDs | E7: Chênh (mm) | F7: Trạng thái / Status | G7: Thông tin cần bổ sung / Required information | H7: Giá trị xác nhận (mm) | I7: Nguồn xác nhận / New reference
A8: ISSUE-P01 | B8: Hai chiều dài tổng của mặt bằng mái / Roof overall lengths | C8: Roof same-sheet overall54794 at top versus54736 at bottom, difference58mm. | D8: P173, P174 | E8: =IF(OR(COUNTBLANK('Dimensions'!G181)>0,COUNTBLANK('Dimensions'!G180)>0),"",'Dimensions'!G181-'Dimensions'!G180) -> 58 | F8: Chưa xác nhận / Open | G8: Xác định mốc đầu/cuối cho chuỗi trên và dưới. / Confirm endpoints of both roof chains.
A9: ISSUE-P02 | B9: Chuỗi cửa gian 2′–3 lệch 10 mm / First opening-bay chain | C9: First lower nave-opening bay printed1135+2250+1125 gives4510 against4500 axis spacing. | D9: P084, P085, P086, P003 | E9: =IF(OR(COUNTBLANK('Dimensions'!G91)>0,COUNTBLANK('Dimensions'!G92)>0,COUNTBLANK('Dimensions'!G93)>0,COUNTBLANK('Dimensions'!G10)>0),"",'Dimensions'!G91+'Dimensions'!G92+'Dimensions'!G93-'Dimensions'!G10) -> 10 | F9: Chưa xác nhận / Open | G9: Xác nhận số 1,135 hoặc các mốc cửa. / Confirm 1,135 or the opening witnesses.
A10: ISSUE-P03 | B10: Biên ngoài cánh nhà / Side-wing outer envelope | C10: Wing envelope28158 differs1mm from26498 axis span plus main-body end margins832+829; wing-specific edge geometry must govern. | D10: P152, P023, P024, P027 | E10: =IF(OR(COUNTBLANK('Dimensions'!G159)>0,COUNTBLANK('Dimensions'!G30)>0,COUNTBLANK('Dimensions'!G31)>0,COUNTBLANK('Dimensions'!G34)>0),"",'Dimensions'!G159+'Dimensions'!G30+'Dimensions'!G31-'Dimensions'!G34) -> 1 | F10: Chưa xác nhận / Open | G10: Cần mốc biên riêng của cánh. / Obtain wing-specific edge offsets.
A11: ISSUE-P04 | B11: Đối chiếu các tờ bản vẽ / Drawing-to-drawing comparison | C11: Resolve drawing-to-drawing differences using the current coordinated revision. Keep each reported dimension tied to its own endpoints. | D11: Files 4–5 | F11: Chưa xác nhận / Open | G11: Xác nhận bộ bản vẽ cùng phiên bản. / Confirm the coordinated drawing revision.
A12: ISSUE-P05 | B12: Nhận dạng hình chữ nhật cung thánh / Sanctuary rectangle identity | C12: Unlabeled sanctuary-front rectangular feature has explicit1900×870mm dimensions but may be a step detail; do not assume it is an altar table. | D12: P115, P123 | F12: Chưa xác nhận / Open | G12: Xác nhận đây là bậc, đồ nội thất hay cấu kiện khác. / Identify the rectangular feature.
A13: EI01 | B13: Chuỗi đỉnh tháp lệch 1 mm / Tower-cap closure | C13: 4125+1814+1892 = 7831; 36920-29090 = 7830 Cap segment closure is 1 mm greater than overall datum difference. Preserve printed inputs and flag; do not silently move cross top or change a segment. | D13: E006, E007, E013, E014, E015 | E13: =IF(OR(COUNTBLANK('Dimensions'!G233)>0,COUNTBLANK('Dimensions'!G234)>0,COUNTBLANK('Dimensions'!G235)>0,COUNTBLANK('Dimensions'!G227)>0,COUNTBLANK('Dimensions'!G226)>0),"",'Dimensions'!G233+'Dimensions'!G234+'Dimensions'!G235-('Dimensions'!G227-'Dimensions'!G226)) -> 1 | F13: Chưa xác nhận / Open | G13: Xác nhận chuỗi đỉnh tháp hoặc cốt thánh giá. / Confirm cap segments or cross level.
A14: EI02 | B14: Chuỗi mặt đứng trung tâm lệch 1 mm / Central facade closure | C14: 621+5959+621 = 7201 versus grid E-D = 7200 Central facade subdimension closure differs by 1 mm. Preserve values and flag; do not silently use 5958 in place of printed 5959. | D14: E021, E029, E030, E031 | E14: =IF(OR(COUNTBLANK('Dimensions'!G249)>0,COUNTBLANK('Dimensions'!G250)>0,COUNTBLANK('Dimensions'!G251)>0,COUNTBLANK('Dimensions'!G241)>0),"",'Dimensions'!G249+'Dimensions'!G250+'Dimensions'!G251-'Dimensions'!G241) -> 1 | F14: Chưa xác nhận / Open | G14: Xác nhận 5,959 mm và hai khoảng 621 mm. / Confirm 5,959 and the two 621 mm offsets.
A15: RFI-S01 | B15: Tổng cao mặt cắt lệch 76 mm / Section overall height | C15: Both section sheets label ridge +12.472 m and courtyard −2.08 m, giving14552 mm; overall dimension14476 mm differs76 mm. Obtain corrected level/overall dimension from designer. | D15: S001, S005, S006, S143 | E15: =IF(OR(COUNTBLANK('Dimensions'!G448)>0,COUNTBLANK('Dimensions'!G311)>0),"",'Dimensions'!G448-'Dimensions'!G311) -> 76 | F15: Chưa xác nhận / Open | G15: Xác nhận cốt sân, cốt nóc và tổng cao. / Resolve the level and overall-height conflict.
A16: RFI-S02 | B16: Cao độ phào ngoài lệch 1 mm / Exterior cornice level | C16: Section +6.325 m and exterior detail chain6325 mm conflict with overall6324 mm on printed sheets12/13. | D16: S003, S088, S148 | E16: =IF(OR(COUNTBLANK('Dimensions'!G453)>0,COUNTBLANK('Dimensions'!G393)>0),"",'Dimensions'!G453-'Dimensions'!G393) -> 1 | F16: Chưa xác nhận / Open | G16: Xác nhận 6,324 hoặc 6,325 mm theo mốc. / Confirm cornice level and witness.
A17: RFI-S03 | B17: Chuỗi cửa cung thánh lệch 1 mm / Sanctuary doorway chain | C17: Printed2554+396=2950 mm, while aligned right-side dimension is2951 mm. Verify reference surfaces/tolerance. | D17: S074, S075, S076 | E17: =IF(OR(COUNTBLANK('Dimensions'!G381)>0,COUNTBLANK('Dimensions'!G379)>0,COUNTBLANK('Dimensions'!G380)>0),"",'Dimensions'!G381-'Dimensions'!G379-'Dimensions'!G380) -> 1 | F17: Chưa xác nhận / Open | G17: Xác nhận các mặt chuẩn của chuỗi cửa. / Confirm doorway reference surfaces.
A18: RFI-S04 | B18: Vòm cửa trong và ngoài lệch 70 mm / Inner and outer door heads | C18: Exterior doorway springline3101+rise1140 gives4241 mm; interior doorway2951+band220+rise1140 gives4311 mm. Clarify70 mm offset and wall locations before modeling a shared opening. | D18: S124, S125, S130, S131, S132, S153, S154 | E18: =IF(OR(COUNTBLANK('Dimensions'!G459)>0,COUNTBLANK('Dimensions'!G458)>0),"",'Dimensions'!G459-'Dimensions'!G458) -> 70 | F18: Chưa xác nhận / Open | G18: Xác nhận hai lớp tường và độ lệch vòm. / Confirm wall planes and arch offset.
A19: RFI-S05 | B19: Độ dốc và kết cấu mái / Roof pitch and structure | C19: Roof form and material notes are supplied, but no pitch angle, purlin spacing/section, truss joints, tile thickness, roof overhang dimensions, or complete support contact elevations are given in these four sheets. Need roof framing/details or CAD geometry. | D19: P212, S002, S023, S081 | F19: Chưa xác nhận / Open | G19: Bổ sung chi tiết hoặc hình học CAD tương ứng. / Supply the relevant dimensioned detail or CAD geometry.
A20: RFI-S06 | B20: Đường cong và hoa văn / Curves and ornaments | C20: Arch bounding widths/rises exist, but radii/centres, curve control points, molding widths/depths, column flutes/capitals, rosette outer diameter/thickness, finial cross-sections and ornamental relief depths are absent. Use original DWG/DXF curves or architect-approved tracing, tagged traced not exact. | D20: Files 6–9 | F20: Chưa xác nhận / Open | G20: Bổ sung chi tiết hoặc hình học CAD tương ứng. / Supply the relevant dimensioned detail or CAD geometry.
A21: RFI-S07 | B21: Tiết diện cột và móng / Column and footing sections | C21: Shown foundation offsets are not column shaft sizes; exact post cross-sections, taper, footing depth, concrete grades and reinforcing details are absent from these architectural sections. | D21: Files 6–9 | F21: Chưa xác nhận / Open | G21: Bổ sung chi tiết hoặc hình học CAD tương ứng. / Supply the relevant dimensioned detail or CAD geometry.
A22: RFI-S08 | B22: Chiều dày lớp hoàn thiện / Finish thicknesses | C22: Concrete floor slab8 cm, veranda roof RC13 cm and material descriptions exist, but natural-stone thickness, sand-fill depth, waterproofing, roof-tile thickness and finish buildup are unspecified. | D22: S045, S080, S081 | F22: Chưa xác nhận / Open | G22: Bổ sung chi tiết hoặc hình học CAD tương ứng. / Supply the relevant dimensioned detail or CAD geometry.
A23: RFI-S09 | B23: Bậc cung thánh và đồ phụng vụ / Sanctuary steps and furniture | C23: Dais elevations are supplied; stair width/run/treads, altar dimensions/location, liturgical furniture and detailed handrails are not dimensioned in these four sheets. | D23: Files 6–9 | F23: Chưa xác nhận / Open | G23: Bổ sung chi tiết hoặc hình học CAD tương ứng. / Supply the relevant dimensioned detail or CAD geometry.
A24: RFI-S10 | B24: Phân biệt hai lớp cửa sổ / Inner and outer window identity | C24: Printed sheet12 exterior is a pair of1000-wide openings with850 sill; interior is one2250-wide opening with650 sill. They correspond to different wall/arcade planes. Do not fuse them into one window without plan confirmation. | D24: S084, S086, S091, S103, S105 | F24: Chưa xác nhận / Open | G24: Bổ sung chi tiết hoặc hình học CAD tương ứng. / Supply the relevant dimensioned detail or CAD geometry.
A25: ISSUE-C01 | B25: Khác biệt chiều dài mặt bằng và mặt đứng / Plan and elevation length | C25: Floor overall67064 and side-elevation67149 differ85mm; the printed/derived endpoint differences are−25mm at approach and+110mm at far end. Geometry/revision intent is not confirmed. Preserve both source chains. | D25: P021, E065, P020, E051, P155, E064 | E25: =IF(OR(COUNTBLANK('Dimensions'!G285)>0,COUNTBLANK('Dimensions'!G28)>0),"",'Dimensions'!G285-'Dimensions'!G28) -> 85 | F25: Chưa xác nhận / Open | G25: Xác nhận hai mốc biên và phiên bản bản vẽ. / Confirm extent witnesses and drawing revision.
A26: ISSUE-C02 | B26: Cao độ nóc mái cánh / Side-wing ridge heights | C26: Main ridge/reference+12.472m is confirmed by other sheets. No exact side-wing ridge height is supplied. Do not assign the main ridge height to the short side-wing ridges. | D26: P212 | F26: Chưa xác nhận / Open | G26: Cần cao độ nóc riêng cho từng cánh. / Supply each side-wing ridge level.
A27: ISSUE-C03 | B27: Giả thiết đối xứng mặt cắt / Section symmetry assumption | C27: 780mm symmetric offset is derived from section widths. Equality of two offsets is an explicit assumption, not independent measurements and not a replacement for differing ground-plan/elevation projections. | D27: S137 | F27: Giả thiết / Assumption | G27: Xác nhận hai biên có đối xứng hay không. / Confirm whether the section edges are symmetric.
A28: ISSUE-C04 | B28: Gán loại cửa vào mặt bằng / Map opening details to locations | C28: Files8/9 provide heights for selected opening types. Exterior paired1000mm openings and inner2250mm openings belong to different facade/arcade planes. Map detail types to exact plan instances; preserve70mm interior/exterior crown difference and unknown curve radii. | D28: P213, S105, S124, S130, S150, S151, S153, S154 | F28: Còn một phần / Partial | G28: Cần mã loại cửa và vị trí từng cửa. / Map detail types to opening instances.
A29: ISSUE-C05 | B29: Khác biệt bề ngang theo mốc đo / Widths by source witness | C29: Floor main exterior22489, opposite elevation22486, and section exterior22388 are different printed dimensions. Do not force these to one dimension without architectural witness confirmation. | D29: P026, E078, S012 | F29: Chưa xác nhận / Open | G29: Xác nhận mốc tường, phào và biên mái. / Confirm wall, molding and roof witnesses.
A30: ISSUE-R01 | B30: Bộ bản vẽ hiện hành / Which drawing revision governs | C30: The CAD file received 24 Oct 2026 (AutoCAD 2007 DWG, created 2011, last saved 23 Oct 2026) numbers its sheets 1–47 and adds a longitudinal section, a +6.324/+8.390 m plan, tower plans, side-wing end elevations, arch-frame details and a tower elevation. Its grid and tower levels agree with the PDFs, but its central facade, sanctuary section and plan dimensioning differ. It has no roof plan. | D30: Source file 10; Files 1–9 | F30: USER CONFIRMED - project design basis; construction issue remains ENGINEERING HOLD | G30: Owner direction, 26 October 2026: use the DWG saved 23 October 2026 as the project design standard. Retain older PDF evidence and unresolved internal conflicts. Responsible designer to issue coordinated construction drawings. | I30: Owner instruction in project chat, 2026-10-26; same DWG SHA-256 as source file 10 (sheets.json).
A31: ISSUE-R02 | B31: Mặt giữa hai tháp / Central facade between the towers | C31: DWG sheet 1 (variant A cut through the nave roof, variant B full elevation) shows one pedimented arched niche with a cross, flanked by crested parapets with fleur-de-lis cresting, two smaller arched niches and a triple-arched window under a rose above the main door. PDF sheet 1 shows a taller screen of three pinnacled gables, which the model followed before the DWG facade adoption on 24 October 2026. Tower geometry and the central 7,200 mm bay are the same. | D31: File 1; source file 10 sheet 1 | F31: Chưa xác nhận / Open | G31: Xác nhận mặt giữa sẽ xây và cung cấp cao độ các tầng trang trí. / Confirm which central facade is to be built and provide its heights.
A32: ISSUE-R03 | B32: Chiều cao mặt cắt cung thánh / Sanctuary section heights | C32: DWG sheet 25 against PDF sheet 5: side-aisle opening chain 160 / 2,544 / 466 / 4,392 against 150 / 2,554 / 396 / 4,462 (both 7,562); inner heights 6,231 and 8,525 against 6,301 and 8,452; right-side opening reference 3,171 (3,170.5) against 2,951. | D32: S074, S075, S076; source file 10 sheet 25 | E32: 70 | F32: Chưa xác nhận / Open | G32: Xác nhận bản mặt cắt cung thánh hiện hành. / Confirm the current sanctuary section.
A33: ISSUE-R04 | B33: Cao độ bục cung thánh / Sanctuary platform level | C33: DWG section 25 dimensions the sanctuary platform 800 mm above the nave floor, with column bases 200 mm above it. The DWG ground plan still labels +0.75 m, as do the PDF plan and section. | D33: P049; source file 10 sheets 5 and 25 | E33: 50 | F33: Chưa xác nhận / Open | G33: Xác nhận +0,75 hay +0,80 m. / Confirm +0.75 m or +0.80 m.
A34: ISSUE-R05 | B34: Nóc mái vẽ và ghi khác nhau / Drawn and labelled ridge differ | C34: The main ridge line is drawn at +12.396 m in DWG sections 24/25 and the side elevation, while every label reads +12.472 m and section A-A draws its ridge at +12.472 m. The 14,476 overall on the sections equals 2,080 + 12,396. Explains RFI-S01; the 76 mm may be a ridge cap. | D34: E049, S001, S006; source file 10 sheets 24, 25, 45 | E34: 76 | F34: Chưa xác nhận / Open | G34: Xác nhận +12,472 là đỉnh ngói nóc hay đỉnh vì kèo. / Confirm whether +12.472 m is the ridge-cap top or the roof apex.
A35: ISSUE-R06 | B35: Đơn vị hình học và đơn vị chèn trong DWG | C35: DWG gốc và DXF mới đều có INSUNITS=1 (inch, đơn vị chèn). Chuỗi trục 4500/7200 và các nhãn cao độ theo m phù hợp cách hiểu hình học mm của mô hình; đây là diễn giải từ bản vẽ, chưa phải xác nhận đơn vị của người thiết kế. Không tự nhân hoặc chia tọa độ theo 25,4. | D35: Tệp CAD nguồn 10; 726 đối tượng kích thước; 137 mốc trục | F35: Chưa xác nhận / ENGINEERING HOLD | G35: Người thiết kế mở DWG trong AutoCAD/ODA, xác nhận đơn vị hình học, tỷ lệ chèn, đơn vị ghi kích thước và phát hành hồ sơ thi công thống nhất. | I35: Kiểm tra trực tiếp 26/10/2026; Autodesk INSUNITS; review/dwg-vietnamese-23102026/kiem-tra-so-lieu.json

Sheet Sources
A2: NGUỒN BẢN VẼ / DRAWING SOURCES
A4: Số cuối tên file khác số tờ in trên bản vẽ. / The filename suffix and printed sheet number are different.
A7: File | B7: Tờ in / Printed sheet | C7: Nội dung / Drawing | D7: Tên file gốc / Original filename | E7: Trang PDF / Page
A8: 1 | B8: 1 | C8: MẶT ĐỨNG CUỐI Twin-tower end | D8: MẶT BẰNG NHÀ THỜ GIÁO XỨ THẠCH BI-Model.pdf 1.pdf | E8: 1
A9: 2 | B9: 2 | C9: MẶT ĐỨNG HAI BÊN Both side elevations | D9: MẶT BẰNG NHÀ THỜ GIÁO XỨ THẠCH BI-Model.pdf 2.pdf | E9: 1
A10: 3 | B10: 3 | C10: MẶT ĐỨNG ĐẦU Opposite gabled end | D10: MẶT BẰNG NHÀ THỜ GIÁO XỨ THẠCH BI-Model.pdf 3.pdf | E10: 1
A11: 4 | B11: 6 | C11: MẶT BẰNG +00 Ground-floor plan | D11: MẶT BẰNG NHÀ THỜ GIÁO XỨ THẠCH BI-Model.pdf 4.pdf | E11: 1
A12: 5 | B12: 11 | C12: MẶT BẰNG MÁI CHẢY Roof plan | D12: MẶT BẰNG NHÀ THỜ GIÁO XỨ THẠCH BI-Model.pdf 5.pdf | E12: 1
A13: 6 | B13: 4 | C13: Mặt cắt thân nhà thờ Nave transverse section | D13: MẶT BẰNG NHÀ THỜ GIÁO XỨ THẠCH BI-Model.pdf 6.pdf | E13: 1
A14: 7 | B14: 5 | C14: Mặt cắt cung thánh Sanctuary transverse section | D14: MẶT BẰNG NHÀ THỜ GIÁO XỨ THẠCH BI-Model.pdf 7.pdf | E14: 1
A15: 8 | B15: 12 | C15: Chi tiết cửa sổ, cột và đỉnh Window, pilaster and finial details | D15: MẶT BẰNG NHÀ THỜ GIÁO XỨ THẠCH BI-Model.pdf 8.pdf | E15: 1
A16: 9 | B16: 13 | C16: Chi tiết cửa đi Doorway bay details | D16: MẶT BẰNG NHÀ THỜ GIÁO XỨ THẠCH BI-Model.pdf 9.pdf | E16: 1
A17: 10 | B17: 1, 3, 5, 14, 24–34, 45–47 | C17: Bộ bản vẽ CAD (DWG), lưu 23/10/2026 CAD drawing set (DWG), saved 2026-10-23 | D17: MẶT BẰNG NHÀ THỜ GIÁO XỨ THẠCH BI.dwg A.dwg | E17: —
A21: QUY ƯỚC MÔ HÌNH / MODEL CONVENTIONS
A23: Đơn vị / Units | C23: 1 Three.js unit = 1 m. Cột mm và m được tính từ trị số gốc. / mm and m columns calculate from the original source value.
A24: Trục X / X | C24: Dọc nhà: trục 1 = 0; chiều dương về trục 12. / Longitudinal: axis 1 = 0, positive toward axis 12.
A25: Trục Y / Y | C25: Chiều cao: sàn gian chính ±0.000 = 0; chiều dương lên trên. / Vertical: main floor = 0, positive upward.
A26: Trục Z / Z | C26: Ngang nhà: trung điểm D–E = 0; chiều dương về G/H/I. / Transverse: midpoint D–E = 0, positive toward G/H/I.
A27: Trục gốc / Axes | C27: Mặt cắt gốc: X → Z mô hình; Y → Y; Z → X. NORMAL là độ dày theo pháp tuyến cục bộ. / Source section axes are remapped.
A28: Tọa độ / Coords | C28: P141–P148 giữ gốc A. Model grid trừ P154 = 13,249 mm để đặt gốc Z tại D–E. / Source A-based coordinates remain intact.
A29: Ô trống / Blank | C29: Chưa có kích thước thì để trống. Số 0 chỉ dùng cho cốt hoặc kết quả bằng 0. / Missing values are not filled with zero.
A30: Khác biệt / Gaps | C30: Giữ riêng các kích thước theo mốc của từng tờ. Xem Open items để xác nhận. / Distinct source witnesses stay separate.
A31: Hình học / Shape | C31: Bán kính vòm, tiết diện trang trí và vài cao độ giao mái còn thiếu. / Some curve, profile and roof-junction dimensions are absent.
A32: Màu sắc / Finish | C32: Các tờ kiến trúc đơn sắc chưa xác định màu sơn, mái hay chóp tháp. / Finish colors are not specified in these drawings.
A33: Phương vị / CRS | C33: Chưa có hướng Bắc, hệ tọa độ địa lý hoặc mốc khảo sát. / No north bearing, geographic CRS or surveyed origin is provided.

Sheet DWG sheets
A2: BẢN VẼ CAD 23/10/2026 / CAD DRAWINGS 2026-10-23
A4: Phiên bản 23102026. 726 kích thước thuộc 27 bản vẽ. Đơn vị mm suy từ chuỗi kích thước và nhãn m; INSUNITS gốc = 1 (inch, đơn vị chèn). Cần người thiết kế xác nhận đơn vị. Số ghi lấy trực tiếp từ chữ số lưu trong CAD. Không dùng để thi công.
A7: Mã / ID | B7: Tờ DWG / DWG sheet | C7: Nhóm / Category | D7: Tiêu đề / Title (VI) | E7: Title (EN) | F7: Trục mô hình / Model axes | G7: PDF tương ứng / Register file | H7: Số kích thước / Dimension objects | I7: Ảnh (không commit) / Image (not committed)
A8: P05 | B8: 5 | C8: plans | D8: MẶT BẰNG +00 NHÀ THỜ GIÁO XỨ THẠCH BI | E8: Ground-floor plan +0.00 | F8: X/Z | G8: 4 | H8: 22 | I8: images/01-plans/P05_ground-floor-plan-0-00.png
A9: P14 | B9: 14 | C9: plans | D9: MẶT BẰNG +6,324m THÂN VÀ +8,390m CUỐI - CÂY THÁP NHÀ THỜ | E9: Plan at +6.324 m (body) and +8.390 m (tower end) | F9: X/Z | G9: — | H9: 16 | I9: images/01-plans/P14_plan-at-6-324-m-body-and-8-390-m-tower-end.png
A10: PT08 | B10: — | C10: plans | D10: MẶT BẰNG KIẾN TRÚC +8,390M ĐỐT MỘT CÂY THÁP | E10: Tower plan at +8.390 m (first tower stage) | F10: u/v | G10: — | H10: 4 | I10: images/01-plans/PT08_tower-plan-at-8-390-m-first-tower-stage.png
A11: PT10 | B11: — | C11: plans | D11: MẶT BẰNG KIẾN TRÚC CUỐI NHÀ THỜ +10,128M | E11: Tower-end plan at +10.128 m | F11: u/v | G11: — | H11: 0 | I11: images/01-plans/PT10_tower-end-plan-at-10-128-m.png
A12: PT15 | B12: — | C12: plans | D12: MẶT BẰNG KIẾN TRÚC CUỐI NHÀ THỜ +15,840M | E12: Tower-end plan at +15.840 m | F12: u/v | G12: — | H12: 0 | I12: images/01-plans/PT15_tower-end-plan-at-15-840-m.png
A13: PT15A | B13: — | C13: plans | D13: MẶT BẰNG +15,84M NHÀ THỜ GX THẠCH BI | E13: Single-tower plan at +15.84 m | F13: u/v | G13: — | H13: 2 | I13: images/01-plans/PT15A_single-tower-plan-at-15-84-m.png
A14: PT23 | B14: — | C14: plans | D14: MẶT BẰNG +23,14M NHÀ THỜ GX THẠCH BI | E14: Single-tower plan at +23.14 m | F14: u/v | G14: — | H14: 0 | I14: images/01-plans/PT23_single-tower-plan-at-23-14-m.png
A15: PT29 | B15: — | C15: plans | D15: MẶT BẰNG +29,09M NHÀ THỜ GX THẠCH BI | E15: Single-tower plan at +29.09 m | F15: u/v | G15: — | H15: 0 | I15: images/01-plans/PT29_single-tower-plan-at-29-09-m.png
A16: P28 | B16: 28 | C16: plans | D16: MẶT BẰNG MỘT GIAN CỬA SỔ | E16: Plan of one window bay | F16: u/v | G16: 8 | H16: 74 | I16: images/01-plans/P28_plan-of-one-window-bay.png
A17: P33 | B17: 33 | C17: plans | D17: (không có tiêu đề) Mặt bằng một gian trục 4–5, cửa đi | E17: Plan of one doorway bay, axes 4–5 (no title) | F17: u/v | G17: 9 | H17: 53 | I17: images/01-plans/P33_plan-of-one-doorway-bay-axes-4-5-no-title.png
A18: E01A | B18: 1 | C18: elevations | D18: MẶT ĐỨNG CUỐI NHÀ THỜ GIÁO XỨ THẠCH BI (bản A, cắt qua mái thân) | E18: Twin-tower end elevation, variant A (cut through the nave roof) | F18: Z/Y | G18: 1 | H18: 23 | I18: images/02-elevations/E01A_twin-tower-end-elevation-variant-a-cut-through-the-nave-roof.png
A19: E01B | B19: 1 | C19: elevations | D19: MẶT ĐỨNG CUỐI NHÀ THỜ GIÁO XỨ THẠCH BI (bản B, mặt đứng đầy đủ) | E19: Twin-tower end elevation, variant B (full elevation) | F19: Z/Y | G19: 1 | H19: 36 | I19: images/02-elevations/E01B_twin-tower-end-elevation-variant-b-full-elevation.png
... A34: D47 | B34: 47 | C34: details | D34: CHI TIẾT MẶT VÌ CUỐN BT CT HAI BÊN CÁNH TG TRỤC C-C, G-G | E34: Reinforced-concrete arch frame, side wings on axes C and G | F34: u/v | G34: — | H34: 15 | I34: images/04-details/D47_reinforced-concrete-arch-frame-side-wings-on-axes-c-and-g.png

Sheet DWG dimensions
A2: KÍCH THƯỚC TRONG FILE CAD / CAD DIMENSION OBJECTS
A4: a/b là hai điểm đo theo trục mô hình của từng bản vẽ (mm). / a and b are the two measuring points in each drawing's model axes (mm). Same-value register IDs are candidates by value only, not confirmed witnesses.
A7: Mã / ID | B7: Bản vẽ / Drawing | C7: Tờ DWG / Sheet | D7: Loại / Kind | E7: Đo được (mm) / Measured | F7: Số in (mm) / Displayed | G7: Trục / Axes | H7: a1 | I7: a2 | J7: b1 | K7: b2 | L7: PDF file | M7: Mã cùng trị số / Same-value register IDs | N7: Handle
A8: DWG0001 | B8: P05 | C8: 5 | D8: horizontal | E8: 67063.6 | F8: 67064 | G8: X/Z | H8: -13218.6 | I8: -14822.8 | J8: 53845 | K8: -14822.8 | L8: 4 | M8: P021 | N8: D7C2D8
A9: DWG0002 | B9: P05 | C9: 5 | D9: horizontal | E9: 12368.6 | F9: 12369 | G9: X/Z | H9: -12368.6 | I9: -13542 | J9: 0 | K9: -14308.8 | L9: 4 | N9: D9F943
A10: DWG0003 | B10: P05 | C10: 5 | D10: horizontal | E10: 7200 | F10: 7200 | G10: X/Z | H10: 36975 | I10: 15184.9 | J10: 44175 | K10: 15327.6 | L10: 4 | M10: P010 P016 P032 | N10: D7C47E
A11: DWG0004 | B11: P05 | C11: 5 | D11: horizontal | E11: 4500 | F11: 4500 | G11: X/Z | H11: 18975 | I11: 15327.6 | J11: 23475 | K11: 15327.6 | L11: 4 | M11: P003 P004 P005 P006 P007 P008 P009 P011 | N11: D7C476
A12: DWG0005 | B12: P05 | C12: 5 | D12: horizontal | E12: 4500 | F12: 4500 | G12: X/Z | H12: 23475 | I12: 15327.6 | J12: 27975 | K12: 15327.6 | L12: 4 | M12: P003 P004 P005 P006 P007 P008 P009 P011 | N12: D7C477
A13: DWG0006 | B13: P05 | C13: 5 | D13: horizontal | E13: 4500 | F13: 4500 | G13: X/Z | H13: 32475 | I13: 15327.6 | J13: 36975 | K13: 15184.9 | L13: 4 | M13: P003 P004 P005 P006 P007 P008 P009 P011 | N13: D7C47B
A14: DWG0007 | B14: P05 | C14: 5 | D14: horizontal | E14: 4500 | F14: 4500 | G14: X/Z | H14: 44175 | I14: 15327.6 | J14: 48675 | K14: 15327.6 | L14: 4 | M14: P003 P004 P005 P006 P007 P008 P009 P011 | N14: D7C481
A15: DWG0008 | B15: P05 | C15: 5 | D15: vertical | E15: 3054 | F15: 3054 | G15: X/Z | H15: -14997.6 | I15: 10414 | J15: -14538.8 | K15: 7360 | L15: 4 | M15: P014 P018 | N15: D7C495
A16: DWG0009 | B16: P05 | C16: 5 | D16: vertical | E16: 2835 | F16: 2835 | G16: X/Z | H16: -14997.6 | I16: 13249 | J16: -14997.6 | K16: 10414 | L16: 4 | M16: P013 P019 P142 | N16: D7C492
A17: DWG0010 | B17: P05 | C17: 5 | D17: vertical | E17: 2835 | F17: 2835 | G17: X/Z | H17: -14538.8 | I17: -10414 | J17: -14538.8 | K17: -13249 | L17: 4 | M17: P013 P019 P142 | N17: D7C49C
A18: DWG0011 | B18: P05 | C18: 5 | D18: vertical | E18: 3054 | F18: 3054 | G18: X/Z | H18: -14538.8 | I18: -7360 | J18: -14538.8 | K18: -10414 | L18: 4 | M18: P014 P018 | N18: D7C49B
A19: DWG0012 | B19: P05 | C19: 5 | D19: vertical | E19: 3760 | F19: 3760 | G19: X/Z | H19: -14538.8 | I19: -3600 | J19: -14538.8 | K19: -7360 | L19: 4 | M19: P015 P017 | N19: D7C49A
A20: DWG0013 | B20: P05 | C20: 5 | D20: vertical | E20: 3760 | F20: 3760 | G20: X/Z | H20: -14538.8 | I20: 7360 | J20: -14538.8 | K20: 3600 | L20: 4 | M20: P015 P017 | N20: D7C496
A21: DWG0014 | B21: P05 | C21: 5 | D21: vertical | E21: 646 | F21: 646 | G21: X/Z | H21: 2331.3 | I21: -12603 | J21: 2331.3 | K21: -13249 | L21: 4 | N21: D7C4AC
A22: DWG0015 | B22: P05 | C22: 5 | D22: vertical | E22: 2370.6 | F22: 2371 | G22: X/Z | H22: 3213.1 | I22: 2979.5 | J22: 2904.8 | K22: 5350 | L22: 4 | N22: D8000C
A23: DWG0016 | B23: P05 | C23: 5 | D23: vertical | E23: 343.4 | F23: 343 | G23: X/Z | H23: 3659.1 | I23: 7360 | J23: 3659 | K23: 7703.5 | L23: 4 | N23: D7C4A6
A24: DWG0017 | B24: P05 | C24: 5 | D24: vertical | E24: 10549 | F24: 10549 | G24: X/Z | H24: 53151 | I24: -10549 | J24: 53824.3 | K24: 0 | L24: 4 | N24: D7C4BE
A25: DWG0018 | B25: P05 | C25: 5 | D25: vertical | E25: 2835 | F25: 2835 | G25: X/Z | H25: 55520.5 | I25: -10414 | J25: 55520.5 | K25: -13249 | L25: 4 | M25: P013 P019 P142 | N25: D7C491
A26: DWG0019 | B26: P05 | C26: 5 | D26: vertical | E26: 3054 | F26: 3054 | G26: X/Z | H26: 55520.5 | I26: -7360 | J26: 55520.5 | K26: -10414 | L26: 4 | M26: P014 P018 | N26: D7C490
A27: DWG0020 | B27: P05 | C27: 5 | D27: vertical | E27: 3760 | F27: 3760 | G27: X/Z | H27: 55520.5 | I27: -3600 | J27: 55520.5 | K27: -7360 | L27: 4 | M27: P015 P017 | N27: D7C48F
A28: DWG0021 | B28: P05 | C28: 5 | D28: vertical | E28: 3054 | F28: 3054 | G28: X/Z | H28: 55520.5 | I28: 10414 | J28: 55520.5 | K28: 7360 | L28: 4 | M28: P014 P018 | N28: D7C488
A29: DWG0022 | B29: P05 | C29: 5 | D29: vertical | E29: 2835 | F29: 2835 | G29: X/Z | H29: 55520.5 | I29: 13249 | J29: 55520.5 | K29: 10414 | L29: 4 | M29: P013 P019 P142 | N29: D7C485
A30: DWG0023 | B30: P14 | C30: 14 | D30: horizontal | E30: 575 | F30: 575 | G30: X/Z | H30: 4900 | I30: -15040 | J30: 5475 | K30: -14800.2 | L30: — | N30: D7D3A9
A31: DWG0024 | B31: P14 | C31: 14 | D31: horizontal | E31: 4500 | F31: 4500 | G31: X/Z | H31: 18975 | I31: -15040 | J31: 23475 | K31: -15040 | L31: — | N31: D7D3B5
A32: DWG0025 | B32: P14 | C32: 14 | D32: horizontal | E32: 4500 | F32: 4500 | G32: X/Z | H32: 23475 | I32: -15040 | J32: 27975 | K32: -15040 | L32: — | N32: D7D3B6
A33: DWG0026 | B33: P14 | C33: 14 | D33: horizontal | E33: 4500 | F33: 4500 | G33: X/Z | H33: 32475 | I33: -15040 | J33: 36975 | K33: -15040 | L33: — | N33: D7D3BA
A34: DWG0027 | B34: P14 | C34: 14 | D34: horizontal | E34: 3599.4 | F34: 3599 | G34: X/Z | H34: 36975 | I34: -15040 | J34: 40574.4 | K34: -15040 | L34: — | N34: D7D3BB
A35: DWG0028 | B35: P14 | C35: 14 | D35: horizontal | E35: 3600.6 | F35: 3601 | G35: X/Z | H35: 40574.4 | I35: -15040 | J35: 44175 | K35: -15040 | L35: — | N35: D7D3BC
A36: DWG0029 | B36: P14 | C36: 14 | D36: horizontal | E36: 4500 | F36: 4500 | G36: X/Z | H36: 44175 | I36: -15040 | J36: 48675 | K36: -15040 | L36: — | N36: D7D3BD
A37: DWG0030 | B37: P14 | C37: 14 | D37: horizontal | E37: 4500 | F37: 4500 | G37: X/Z | H37: 5475 | I37: -14800.2 | J37: 9975 | K37: -15040 | L37: — | N37: D7D3AC
A38: DWG0031 | B38: P14 | C38: 14 | D38: vertical | E38: 14500.5 | F38: 14500 | G38: X/Z | H38: 16457.6 | I38: -7250 | J38: 16960.7 | K38: 7250.5 | L38: — | N38: D7D3CF
A39: DWG0032 | B39: P14 | C39: 14 | D39: vertical | E39: 20498.5 | F39: 20498 | G39: X/Z | H39: 17342.8 | I39: -10249 | J39: 17545.3 | K39: 10249.5 | L39: — | N39: D7D3D2
A40: DWG0033 | B40: P14 | C40: 14 | D40: vertical | E40: 2835 | F40: 2835 | G40: X/Z | H40: 55665 | I40: -13249 | J40: 55665 | K40: -10414 | L40: — | N40: D7D3C1
A41: DWG0034 | B41: P14 | C41: 14 | D41: vertical | E41: 3600 | F41: 3600 | G41: X/Z | H41: 55665 | I41: -3600 | J41: 55665 | K41: 0 | L41: — | N41: D7D3CA
... A51: DWG0044 | B51: PT15A | C51: — | D51: vertical | E51: 4130 | F51: 4130 | G51: u/v | H51: 5228.8 | I51: 3373.3 | J51: 5228.8 | K51: 7503.3 | L51: — | N51: DB0C03
A52: DWG0045 | B52: P28 | C52: 28 | D52: horizontal | E52: 4500 | F52: 4500 | G52: u/v | H52: 2462.3 | I52: 1116.1 | J52: 6962.3 | K52: 1116.1 | L52: 8 | M52: S082 | N52: DAD673
A53: DWG0046 | B53: P28 | C53: 28 | D53: horizontal | E53: 225 | F53: 225 | G53: u/v | H53: 2237.3 | I53: 1984.3 | J53: 2462.3 | K53: 1984.3 | L53: 8 | N53: DAD5AC
...

Sheet DWG levels
A2: CAO ĐỘ TRONG FILE CAD / CAD LEVEL LABELS
A4: So nhãn cao độ với đỉnh ký hiệu cao độ vẽ bên dưới. / Each printed level against the apex of its drawn marker.
A7: Bản vẽ / Drawing | B7: Nhãn / Label | C7: Ghi (mm) / Printed | D7: Theo ký hiệu (mm) / Marker | E7: Chênh (mm) / Δ | F7: Kiểm tra / Check | G7: Cơ sở / Basis
A8: P05 | B8: - 0,48 M | C8: -480 | G8: plan label (no marker geometry)
A9: P05 | B9: - 0,32 M | C9: -320 | G9: plan label (no marker geometry)
A10: P05 | B10: - 0,32 M | C10: -320 | G10: plan label (no marker geometry)
A11: P05 | B11: + 00 M | C11: 0 | G11: plan label (no marker geometry)
A12: P05 | B12: - 0,32 M | C12: -320 | G12: plan label (no marker geometry)
A13: P05 | B13: - 0,32 M | C13: -320 | G13: plan label (no marker geometry)
A14: P05 | B14: + 0,75 M | C14: 750 | G14: plan label (no marker geometry)
A15: P05 | B15: + 0,15 M | C15: 150 | G15: plan label (no marker geometry)
A16: P05 | B16: + 0,15 M | C16: 150 | G16: plan label (no marker geometry)
A17: P05 | B17: - 0,32 M | C17: -320 | G17: plan label (no marker geometry)
A18: P05 | B18: - 0,32 M | C18: -320 | G18: plan label (no marker geometry)
A19: P05 | B19: + 0,15 M | C19: 150 | G19: plan label (no marker geometry)
... A27: PT10 | B27: +8,390M | C27: 8390 | G27: plan label (no marker geometry)
A28: E01A | B28: + 36,920M | C28: 36920 | D28: 36920 | E28: 0 | F28: matches | G28: marker apex − ±0.000 marker apex (same symbol)
A29: E01A | B29: + 29,09M | C29: 29090 | D29: 29090 | E29: 0 | F29: matches | G29: marker apex − ±0.000 marker apex (same symbol)
A30: E01A | B30: + 23,140M | C30: 23140 | D30: 23140 | E30: 0 | F30: matches | G30: marker apex − ±0.000 marker apex (same symbol)
A31: E01A | B31: + 15,840M | C31: 15840 | D31: 15840 | E31: 0 | F31: matches | G31: marker apex − ±0.000 marker apex (same symbol)
A32: E01A | B32: + 8,390M | C32: 8390 | D32: 8390 | E32: 0 | F32: matches | G32: marker apex − ±0.000 marker apex (same symbol)
A33: E01A | B33: +00M | C33: 0 | D33: 0 | E33: 0 | F33: matches | G33: marker apex − ±0.000 marker apex (same symbol)
A34: E01A | B34: - 2,08M | C34: -2080 | D34: -2080 | E34: 0 | F34: matches | G34: marker apex − ±0.000 marker apex (same symbol)
A35: E01B | B35: + 36,920M | C35: 36920 | D35: 36920 | E35: 0 | F35: matches | G35: marker apex − ±0.000 marker apex (same symbol)
A36: E01B | B36: + 29,09M | C36: 29090 | D36: 29090 | E36: 0 | F36: matches | G36: marker apex − ±0.000 marker apex (same symbol)
A37: E01B | B37: + 23,140M | C37: 23140 | D37: 23140 | E37: 0 | F37: matches | G37: marker apex − ±0.000 marker apex (same symbol)
A38: E01B | B38: + 15,840M | C38: 15840 | D38: 15840 | E38: 0 | F38: matches | G38: marker apex − ±0.000 marker apex (same symbol)
A39: E01B | B39: + 8,390M | C39: 8390 | D39: 8390 | E39: 0 | F39: matches | G39: marker apex − ±0.000 marker apex (same symbol)
... A79: S45 | B79: +00M | C79: 0 | D79: 0 | E79: 0 | F79: matches | G79: marker apex − ±0.000 marker apex (same symbol)
A80: S45 | B80: MẶT SÂN - 2,08M | C80: -2080 | G80: plan label (no marker geometry)
A81: S45 | B81: + 17,829M | C81: 17829 | D81: 17829.2 | E81: 0.2 | F81: matches | G81: marker apex − ±0.000 marker apex (same symbol)
A82: S45 | B82: + 12,472M | C82: 12472 | D82: 12471.9 | E82: -0.1 | F82: matches | G82: marker apex − ±0.000 marker apex (same symbol)
A83: S45 | B83: + 8,575M | C83: 8575 | D83: 8575.4 | E83: 0.4 | F83: matches | G83: marker apex − ±0.000 marker apex (same symbol)
A84: S45 | B84: + 6,324M | C84: 6324 | D84: 6323.9 | E84: -0.1 | F84: matches | G84: marker apex − ±0.000 marker apex (same symbol)
A85: S45 | B85: + 00 | C85: 0 | D85: 0 | E85: 0 | F85: matches | G85: marker apex − ±0.000 marker apex (same symbol)
A86: S45 | B86: MẶT SÂN - 2,08M | C86: -2080 | D86: -2080 | E86: 0 | F86: matches | G86: marker apex − ±0.000 marker apex (same symbol)

Sheet DWG grid check
A2: KIỂM TRA LƯỚI TRỤC / GRID CHECK
A4: Đường tim vẽ trong DWG so với Model grid. / Drawn centrelines (layer “duong tim”) against the Model grid.
A7: Bản vẽ / Drawing | B7: Trục 3D / Axis | C7: Trục / Grid | D7: Register (mm) | E7: DWG (mm) | F7: Chênh (mm) / Δ
A8: P05 | B8: X | C8: 1 | D8: 0 | E8: 0 | F8: 0
A9: P05 | B9: X | C9: 2 | D9: 4900 | E9: 4900 | F9: 0
A10: P05 | B10: X | C10: 2′ | D10: 5475 | E10: 5475 | F10: 0
A11: P05 | B11: X | C11: 3 | D11: 9975 | E11: 9975 | F11: 0
A12: P05 | B12: X | C12: 4 | D12: 14475 | E12: 14475 | F12: 0
A13: P05 | B13: X | C13: 5 | D13: 18975 | E13: 18975 | F13: 0
A14: P05 | B14: X | C14: 6 | D14: 23475 | E14: 23475 | F14: 0
A15: P05 | B15: X | C15: 7 | D15: 27975 | E15: 27975 | F15: 0
A16: P05 | B16: X | C16: 8 | D16: 32475 | E16: 32475 | F16: 0
